Workbook

Sheet Sheet1
A1: id | B1: name | C1: blurb | D1: goal | E1: pledged | F1: state | G1: country | H1: currency | I1: deadline | J1: launched_at | K1: staff_pick | L1: backers_count | M1: spotlight | N1: Category and Sub-Category | O1: Percent Funded | P1: Average Donation | Q1: Category | R1: Sub-Category | S1: Date Created Conversion | T1: Date Ended Conversion
A2: 0 | B2: GIRLS STATE a new musical comedy TV project | C2: In this new TV show "All Politics is Vocal" as high school girls campaign, sing and cheer to be elected Governor of their summer camp. | D2: 8500 | E2: 11633 | F2: successful | G2: US | H2: USD | I2: 1437620400 | J2: 1434931811 | K2: FALSE | L2: 182 | M2: TRUE | N2: film & video/television | O2: =(E2/D2)*100 -> 136.85882 | P2: =IF(E2>0,E2/L2,"N/A") -> 63.917582 | Q2: film & video | R2: television | S2: =(((J2/60)/60)/24)+DATE(1970,1,1) -> 42177.007 | T2: =(((I2/60)/60/24)+DATE(1970,1,1)) -> 42208.125
A3: 1 | B3: FannibalFest Fan Convention | C3: A Hannibal TV Show Fan Convention and Art Collective | D3: 10275 | E3: 14653 | F3: successful | G3: US | H3: USD | I3: 1488464683 | J3: 1485872683 | K3: FALSE | L3: 79 | M3: TRUE | N3: film & video/television | O3: =(E3/D3)*100 -> 142.60827 | P3: =IF(E3>0,E3/L3,"N/A") -> 185.48101 | Q3: film & video | R3: television | S3: =(((J3/60)/60)/24)+DATE(1970,1,1) -> 42766.6 | T3: =(((I3/60)/60/24)+DATE(1970,1,1)) -> 42796.6
A4: 2 | B4: Charlie teaser completion | C4: Completion fund for post-production for teaser of British crime/drama tv series about a girl who sells morals for money | D4: 500 | E4: 525 | F4: successful | G4: GB | H4: GBP | I4: 1455555083 | J4: 1454691083 | K4: FALSE | L4: 35 | M4: TRUE | N4: film & video/television | O4: =(E4/D4)*100 -> 105 | P4: =IF(E4>0,E4/L4,"N/A") -> 15 | Q4: film & video | R4: television | S4: =(((J4/60)/60)/24)+DATE(1970,1,1) -> 42405.702 | T4: =(((I4/60)/60/24)+DATE(1970,1,1)) -> 42415.702
A5: 3 | B5: Unsure/Positive: A Dramedy Series About Life with HIV | C5: We already produced the *very* beginning of this story. Help us to see it through? | D5: 10000 | E5: 10390 | F5: successful | G5: US | H5: USD | I5: 1407414107 | J5: 1404822107 | K5: FALSE | L5: 150 | M5: TRUE | N5: film & video/television | O5: =(E5/D5)*100 -> 103.9 | P5: =IF(E5>0,E5/L5,"N/A") -> 69.266667 | Q5: film & video | R5: television | S5: =(((J5/60)/60)/24)+DATE(1970,1,1) -> 41828.515 | T5: =(((I5/60)/60/24)+DATE(1970,1,1)) -> 41858.515
A6: 4 | B6: Party Monsters | C6: 19th centuryâ€™s most notorious literary characters, out of step with the times, find comradery as roommates in modern day Los Angeles. | D6: 44000 | E6: 54116.28 | F6: successful | G6: US | H6: USD | I6: 1450555279 | J6: 1447963279 | K6: FALSE | L6: 284 | M6: TRUE | N6: film & video/television | O6: =(E6/D6)*100 -> 122.99155 | P6: =IF(E6>0,E6/L6,"N/A") -> 190.55028 | Q6: film & video | R6: television | S6: =(((J6/60)/60)/24)+DATE(1970,1,1) -> 42327.834 | T6: =(((I6/60)/60/24)+DATE(1970,1,1)) -> 42357.834
A7: 5 | B7: Terry Matthews to be the NEXT star on the Network Television | C7: The BBQ Daddy will be Filming the 1st episode of the Next Hit series to come to Network Television "Bailout My Cookout" | D7: 3999 | E7: 4390 | F7: successful | G7: US | H7: USD | I7: 1469770500 | J7: 1468362207 | K7: FALSE | L7: 47 | M7: TRUE | N7: film & video/television | O7: =(E7/D7)*100 -> 109.77744 | P7: =IF(E7>0,E7/L7,"N/A") -> 93.404255 | Q7: film & video | R7: television | S7: =(((J7/60)/60)/24)+DATE(1970,1,1) -> 42563.933 | T7: =(((I7/60)/60/24)+DATE(1970,1,1)) -> 42580.233
A8: 6 | B8: POINT HOPE | C8: The story of "Point Hope" will honor, respect, and share the beauty and traditions of the Alaska Natives in Point Hope, AK: the Inupiat | D8: 8000 | E8: 8519 | F8: successful | G8: US | H8: USD | I8: 1402710250 | J8: 1401846250 | K8: FALSE | L8: 58 | M8: TRUE | N8: film & video/television | O8: =(E8/D8)*100 -> 106.4875 | P8: =IF(E8>0,E8/L8,"N/A") -> 146.87931 | Q8: film & video | R8: television | S8: =(((J8/60)/60)/24)+DATE(1970,1,1) -> 41794.072 | T8: =(((I8/60)/60/24)+DATE(1970,1,1)) -> 41804.072
A9: 7 | B9: Skin: Film Production By 14 Year Old Aniya Wolfe | C9: Secrets bond three unfortunate teens who are facing issues that are common among youth today. And for one, it becomes too much to bear. | D9: 9000 | E9: 9110 | F9: successful | G9: US | H9: USD | I9: 1467680867 | J9: 1464224867 | K9: FALSE | L9: 57 | M9: TRUE | N9: film & video/television | O9: =(E9/D9)*100 -> 101.22222 | P9: =IF(E9>0,E9/L9,"N/A") -> 159.82456 | Q9: film & video | R9: television | S9: =(((J9/60)/60)/24)+DATE(1970,1,1) -> 42516.047 | T9: =(((I9/60)/60/24)+DATE(1970,1,1)) -> 42556.047
A10: 8 | B10: Sizzling in the Kitchen Flynn Style | C10: Help us raise the funds to film our pilot episode! | D10: 3500 | E10: 3501.52 | F10: successful | G10: US | H10: USD | I10: 1460754000 | J10: 1460155212 | K10: FALSE | L10: 12 | M10: TRUE | N10: film & video/television | O10: =(E10/D10)*100 -> 100.04343 | P10: =IF(E10>0,E10/L10,"N/A") -> 291.79333 | Q10: film & video | R10: television | S10: =(((J10/60)/60)/24)+DATE(1970,1,1) -> 42468.945 | T10: =(((I10/60)/60/24)+DATE(1970,1,1)) -> 42475.875
A11: 9 | B11: The Academy: Mockumentary Sitcom TV Pilot | C11: Capturing everyday life at Falkirk Academy, a fictitious elite private high school where "everyday life" is anything but normal. | D11: 500 | E11: 629.99 | F11: successful | G11: US | H11: USD | I11: 1460860144 | J11: 1458268144 | K11: FALSE | L11: 20 | M11: TRUE | N11: film & video/television | O11: =(E11/D11)*100 -> 125.998 | P11: =IF(E11>0,E11/L11,"N/A") -> 31.4995 | Q11: film & video | R11: television | S11: =(((J11/60)/60)/24)+DATE(1970,1,1) -> 42447.104 | T11: =(((I11/60)/60/24)+DATE(1970,1,1)) -> 42477.104
A12: 10 | B12: Big in Beijing. A reality tv show about eccentric Beijing. | C12: Making a reality show casting the real elites of China. They are fun, young, wild, and ambitious. Filmed in Beijing with real risks. | D12: 3000 | E12: 3015 | F12: successful | G12: US | H12: USD | I12: 1403660279 | J12: 1400636279 | K12: FALSE | L12: 19 | M12: TRUE | N12: film & video/television | O12: =(E12/D12)*100 -> 100.5 | P12: =IF(E12>0,E12/L12,"N/A") -> 158.68421 | Q12: film & video | R12: television | S12: =(((J12/60)/60)/24)+DATE(1970,1,1) -> 41780.068 | T12: =(((I12/60)/60/24)+DATE(1970,1,1)) -> 41815.068
A13: 11 | B13: 2016 TAPR DCC Video on HamRadioNow | C13: HamRadioNow will produce YouTube video of the complete 2016 ARRL & TAPR Amateur Radio (Ham Radio) Digital Communications Conference | D13: 5000 | E13: 6025 | F13: successful | G13: US | H13: USD | I13: 1471834800 | J13: 1469126462 | K13: FALSE | L13: 75 | M13: TRUE | N13: film & video/television | O13: =(E13/D13)*100 -> 120.5 | P13: =IF(E13>0,E13/L13,"N/A") -> 80.333333 | Q13: film & video | R13: television | S13: =(((J13/60)/60)/24)+DATE(1970,1,1) -> 42572.778 | T13: =(((I13/60)/60/24)+DATE(1970,1,1)) -> 42604.125
... A245: 243 | B245: Following Boruch | C245: A Hasidic man reaches a turning point in his recovery from mental illness and addiction, and is determined to start a new life. | D245: 25000 | E245: 25648 | F245: successful | G245: US | H245: USD | I245: 1393031304 | J245: 1390439304 | K245: TRUE | L245: 328 | M245: TRUE | N245: film & video/documentary | O245: =(E245/D245)*100 -> 102.592 | P245: =IF(E245>0,E245/L245,"N/A") -> 78.195122 | Q245: film & video | R245: documentary | S245: =(((J245/60)/60)/24)+DATE(1970,1,1) -> 41662.048 | T245: =(((I245/60)/60/24)+DATE(1970,1,1)) -> 41692.048
A246: 244 | B246: 39756 | C246: A transmedia-project to amass a library of footage shot the day Obama was elected, for (1) a feature documentary, (2) an interactive web history | D246: 3500 | E246: 3981.5 | F246: successful | G246: US | H246: USD | I246: 1268723160 | J246: 1265269559 | K246: TRUE | L246: 84 | M246: TRUE | N246: film & video/documentary | O246: =(E246/D246)*100 -> 113.75714 | P246: =IF(E246>0,E246/L246,"N/A") -> 47.39881 | Q246: film & video | R246: documentary | S246: =(((J246/60)/60)/24)+DATE(1970,1,1) -> 40213.324 | T246: =(((I246/60)/60/24)+DATE(1970,1,1)) -> 40253.296
A247: 245 | B247: We Lived Alone: The Connie Converse Documentary | C247: "Human society fascinates me & awes me & fills me with grief & joy; I just can't find my place to plug into it." - C. Converse, 8/10/74 | D247: 5000 | E247: 5186 | F247: successful | G247: US | H247: USD | I247: 1345079785 | J247: 1342487785 | K247: TRUE | L247: 96 | M247: TRUE | N247: film & video/documentary | O247: =(E247/D247)*100 -> 103.72 | P247: =IF(E247>0,E247/L247,"N/A") -> 54.020833 | Q247: film & video | R247: documentary | S247: =(((J247/60)/60)/24)+DATE(1970,1,1) -> 41107.053 | T247: =(((I247/60)/60/24)+DATE(1970,1,1)) -> 41137.053
A248: 246 | B248: LEAVING ATLANTA THE FILM | C248: From 1979 to 1981 twenty-nine Black children in Atlanta were murdered and the others terrified. This is our story... | D248: 5000 | E248: 15273 | F248: successful | G248: US | H248: USD | I248: 1292665405 | J248: 1288341805 | K248: TRUE | L248: 223 | M248: TRUE | N248: film & video/documentary | O248: =(E248/D248)*100 -> 305.46 | P248: =IF(E248>0,E248/L248,"N/A") -> 68.488789 | Q248: film & video | R248: documentary | S248: =(((J248/60)/60)/24)+DATE(1970,1,1) -> 40480.363 | T248: =(((I248/60)/60/24)+DATE(1970,1,1)) -> 40530.405
A249: 247 | B249: Deja-Vu: Dissecting Memory on Camera | C249: A young neuroscientist attempts to reconnect with his ailing father by obsessively studying old family footage. | D249: 5000 | E249: 6705 | F249: successful | G249: US | H249: USD | I249: 1287200340 | J249: 1284042614 | K249: TRUE | L249: 62 | M249: TRUE | N249: film & video/documentary | O249: =(E249/D249)*100 -> 134.1 | P249: =IF(E249>0,E249/L249,"N/A") -> 108.14516 | Q249: film & video | R249: documentary | S249: =(((J249/60)/60)/24)+DATE(1970,1,1) -> 40430.604 | T249: =(((I249/60)/60/24)+DATE(1970,1,1)) -> 40467.152
A250: 248 | B250: Far Out Isn't Far Enough: The Tomi Ungerer Story | C250: FAR OUT ISN'T FAR ENOUGH depicts one man's wild, lifelong adventure of testing societal boundaries through his use of subversive art. | D250: 85000 | E250: 86133 | F250: successful | G250: US | H250: USD | I250: 1325961309 | J250: 1322073309 | K250: TRUE | L250: 146 | M250: TRUE | N250: film & video/documentary | O250: =(E250/D250)*100 -> 101.33294 | P250: =IF(E250>0,E250/L250,"N/A") -> 589.95205 | Q250: film & video | R250: documentary | S250: =(((J250/60)/60)/24)+DATE(1970,1,1) -> 40870.774 | T250: =(((I250/60)/60/24)+DATE(1970,1,1)) -> 40915.774
A251: 249 | B251: Bee the Change National Campaign - Vanishing of the Bees documentary | C251: Bee The Change Campaign utilizes the documentary Vanishing of the Bees to raise awareness about bees and our environment, inspiring people into action | D251: 10000 | E251: 11292 | F251: successful | G251: US | H251: USD | I251: 1282498800 | J251: 1275603020 | K251: TRUE | L251: 235 | M251: TRUE | N251: film & video/documentary | O251: =(E251/D251)*100 -> 112.92 | P251: =IF(E251>0,E251/L251,"N/A") -> 48.051064 | Q251: film & video | R251: documentary | S251: =(((J251/60)/60)/24)+DATE(1970,1,1) -> 40332.924 | T251: =(((I251/60)/60/24)+DATE(1970,1,1)) -> 40412.736
A252: 250 | B252: BOONE- THE DOCUMENTARY | C252: Three young farmers risk land and friendship to stand up to the USDA. An experiential film about living a life of self reliance. | D252: 30000 | E252: 31675 | F252: successful | G252: US | H252: USD | I252: 1370525691 | J252: 1367933691 | K252: TRUE | L252: 437 | M252: TRUE | N252: film & video/documentary | O252: =(E252/D252)*100 -> 105.58333 | P252: =IF(E252>0,E252/L252,"N/A") -> 72.482838 | Q252: film & video | R252: documentary | S252: =(((J252/60)/60)/24)+DATE(1970,1,1) -> 41401.566 | T252: =(((I252/60)/60/24)+DATE(1970,1,1)) -> 41431.566
A253: 251 | B253: The Way Back to Yarasquin: A Coffee Pilgrimage | C253: Remarkably devoted, Mayra is single-handedly sourcing small farm, single-origin coffee from her rural village in Honduras. | D253: 3500 | E253: 4395 | F253: successful | G253: US | H253: USD | I253: 1337194800 | J253: 1334429646 | K253: TRUE | L253: 77 | M253: TRUE | N253: film & video/documentary | O253: =(E253/D253)*100 -> 125.57143 | P253: =IF(E253>0,E253/L253,"N/A") -> 57.077922 | Q253: film & video | R253: documentary | S253: =(((J253/60)/60)/24)+DATE(1970,1,1) -> 41013.788 | T253: =(((I253/60)/60/24)+DATE(1970,1,1)) -> 41045.792
A254: 252 | B254: Good Grief: Making CARTOON COLLEGE - a documentary about comics | C254: The definitive story of indie comics and the foremost institution of higher learning for those who draw them. | D254: 5000 | E254: 9228 | F254: successful | G254: US | H254: USD | I254: 1275364740 | J254: 1269878058 | K254: TRUE | L254: 108 | M254: TRUE | N254: film & video/documentary | O254: =(E254/D254)*100 -> 184.56 | P254: =IF(E254>0,E254/L254,"N/A") -> 85.444444 | Q254: film & video | R254: documentary | S254: =(((J254/60)/60)/24)+DATE(1970,1,1) -> 40266.663 | T254: =(((I254/60)/60/24)+DATE(1970,1,1)) -> 40330.166
A255: 253 | B255: Leon Claxton's HARLEM IN HAVANA | C255: A so-called â€œJig Showâ€ innovates music and theatre and gives birth to entertainment icons that would one day write American pop culture | D255: 1500 | E255: 1511 | F255: successful | G255: US | H255: USD | I255: 1329320235 | J255: 1326728235 | K255: TRUE | L255: 7 | M255: TRUE | N255: film & video/documentary | O255: =(E255/D255)*100 -> 100.73333 | P255: =IF(E255>0,E255/L255,"N/A") -> 215.85714 | Q255: film & video | R255: documentary | S255: =(((J255/60)/60)/24)+DATE(1970,1,1) -> 40924.651 | T255: =(((I255/60)/60/24)+DATE(1970,1,1)) -> 40954.651
A256: 254 | B256: "I Clown You" Documentary | C256: "I Clown You" is a documentary about Israeli medical clowns and clowning as an art of challenging the norm. | D256: 24000 | E256: 28067.34 | F256: successful | G256: US | H256: USD | I256: 1445047200 | J256: 1442443910 | K256: TRUE | L256: 314 | M256: TRUE | N256: film & video/documentary | O256: =(E256/D256)*100 -> 116.94725 | P256: =IF(E256>0,E256/L256,"N/A") -> 89.386433 | Q256: film & video | R256: documentary | S256: =(((J256/60)/60)/24)+DATE(1970,1,1) -> 42263.953 | T256: =(((I256/60)/60/24)+DATE(1970,1,1)) -> 42294.083
A257: 255 | B257: xoxosms: a documentary about love in the 21st century | C257: xoxosms is a documentary about first love, long distance and Skype. | D257: 8000 | E257: 8538.66 | F257: successful | G257: US | H257: USD | I257: 1300275482 | J257: 1297687082 | K257: TRUE | L257: 188 | M257: TRUE | N257: film & video/documentary | O257: =(E257/D257)*100 -> 106.73325 | P257: =IF(E257>0,E257/L257,"N/A") -> 45.418404 | Q257: film & video | R257: documentary | S257: =(((J257/60)/60)/24)+DATE(1970,1,1) -> 40588.526 | T257: =(((I257/60)/60/24)+DATE(1970,1,1)) -> 40618.485
A258: 256 | B258: POW WOW: Share the arts community of Hawaii | C258: Help share the art and community of Pow Wow, a contemporary art movement in Hawaii, with the rest of the world. #powwowhawaii | D258: 13000 | E258: 18083 | F258: successful | G258: US | H258: USD | I258: 1363458467 | J258: 1360866467 | K258: TRUE | L258: 275 | M258: TRUE | N258: film & video/documentary | O258: =(E258/D258)*100 -> 139.1 | P258: =IF(E258>0,E258/L258,"N/A") -> 65.756364 | Q258: film & video | R258: documentary | S258: =(((J258/60)/60)/24)+DATE(1970,1,1) -> 41319.769 | T258: =(((I258/60)/60/24)+DATE(1970,1,1)) -> 41349.769
... A3887: 3885 | B3887: THE SESSIONS - The Beatles at Abbey Road Studios (Canceled) | C3887: A LIVE musical spectacular theatrical experience of The Beatles recording sessions at Abbey Road Studios. | D3887: 375000 | E3887: 0 | F3887: canceled | G3887: US | H3887: USD | I3887: 1462834191 | J3887: 1460242191 | K3887: FALSE | L3887: 0 | M3887: FALSE | N3887: theater/musical | O3887: =(E3887/D3887)*100 -> 0 | P3887: =IF(E3887>0,E3887/L3887,"N/A") -> N/A | Q3887: theater | R3887: musical | S3887: =(((J3887/60)/60)/24)+DATE(1970,1,1) -> 42469.951 | T3887: =(((I3887/60)/60/24)+DATE(1970,1,1)) -> 42499.951
A3888: 3886 | B3888: a (Canceled) | C3888: 1 | D3888: 10000 | E3888: 0 | F3888: canceled | G3888: AU | H3888: AUD | I3888: 1418275702 | J3888: 1415683702 | K3888: FALSE | L3888: 0 | M3888: FALSE | N3888: theater/musical | O3888: =(E3888/D3888)*100 -> 0 | P3888: =IF(E3888>0,E3888/L3888,"N/A") -> N/A | Q3888: theater | R3888: musical | S3888: =(((J3888/60)/60)/24)+DATE(1970,1,1) -> 41954.228 | T3888: =(((I3888/60)/60/24)+DATE(1970,1,1)) -> 41984.228
A3889: 3887 | B3889: SUPER!: An Original Musical (KC Fringe 2015) (Canceled) | C3889: "SUPER!: An Original Musical" is an original work written by Ryan Hruza. This campaign is to fund the production and pay the cast/crew! | D3889: 2000 | E3889: 35 | F3889: canceled | G3889: US | H3889: USD | I3889: 1430517600 | J3889: 1426538129 | K3889: FALSE | L3889: 2 | M3889: FALSE | N3889: theater/musical | O3889: =(E3889/D3889)*100 -> 1.75 | P3889: =IF(E3889>0,E3889/L3889,"N/A") -> 17.5 | Q3889: theater | R3889: musical | S3889: =(((J3889/60)/60)/24)+DATE(1970,1,1) -> 42079.858 | T3889: =(((I3889/60)/60/24)+DATE(1970,1,1)) -> 42125.917
A3890: 3888 | B3890: Popinjay Productions' The Odyssey | C3890: We are devising a vibrant new adaptation of Homer's The Odyssey featuring dynamic storytelling, stunning visuals and original music. | D3890: 2000 | E3890: 542 | F3890: failed | G3890: GB | H3890: GBP | I3890: 1488114358 | J3890: 1485522358 | K3890: FALSE | L3890: 14 | M3890: FALSE | N3890: theater/plays | O3890: =(E3890/D3890)*100 -> 27.1 | P3890: =IF(E3890>0,E3890/L3890,"N/A") -> 38.714286 | Q3890: theater | R3890: plays | S3890: =(((J3890/60)/60)/24)+DATE(1970,1,1) -> 42762.546 | T3890: =(((I3890/60)/60/24)+DATE(1970,1,1)) -> 42792.546
A3891: 3889 | B3891: Sherri's Playhouse Present's A Heavenly Hand! | C3891: A romantic comedy about a girl trying to figure out what to do with her life and an angel who comes to help her. | D3891: 8000 | E3891: 118 | F3891: failed | G3891: US | H3891: USD | I3891: 1420413960 | J3891: 1417651630 | K3891: FALSE | L3891: 9 | M3891: FALSE | N3891: theater/plays | O3891: =(E3891/D3891)*100 -> 1.475 | P3891: =IF(E3891>0,E3891/L3891,"N/A") -> 13.111111 | Q3891: theater | R3891: plays | S3891: =(((J3891/60)/60)/24)+DATE(1970,1,1) -> 41977.005 | T3891: =(((I3891/60)/60/24)+DATE(1970,1,1)) -> 42008.976
A3892: 3890 | B3892: Something Wicked This Way Comes | C3892: Will Power Troupe is the only US group invited to perform in London's Shakespeare Festival. We need your help to bring the USA to UK! | D3892: 15000 | E3892: 2524 | F3892: failed | G3892: US | H3892: USD | I3892: 1439662344 | J3892: 1434478344 | K3892: FALSE | L3892: 8 | M3892: FALSE | N3892: theater/plays | O3892: =(E3892/D3892)*100 -> 16.826667 | P3892: =IF(E3892>0,E3892/L3892,"N/A") -> 315.5 | Q3892: theater | R3892: plays | S3892: =(((J3892/60)/60)/24)+DATE(1970,1,1) -> 42171.759 | T3892: =(((I3892/60)/60/24)+DATE(1970,1,1)) -> 42231.759
A3893: 3891 | B3893: Out of the Box: A Mime Story | C3893: A comedy about a mime who dreams of becoming a stand up comedian. | D3893: 800 | E3893: 260 | F3893: failed | G3893: US | H3893: USD | I3893: 1427086740 | J3893: 1424488244 | K3893: FALSE | L3893: 7 | M3893: FALSE | N3893: theater/plays | O3893: =(E3893/D3893)*100 -> 32.5 | P3893: =IF(E3893>0,E3893/L3893,"N/A") -> 37.142857 | Q3893: theater | R3893: plays | S3893: =(((J3893/60)/60)/24)+DATE(1970,1,1) -> 42056.132 | T3893: =(((I3893/60)/60/24)+DATE(1970,1,1)) -> 42086.208
A3894: 3892 | B3894: The Sea Horse, presented by Different Stages | C3894: Saloon owner Gertude Blum mistrusts all men and scorns love, but sailor Harry Bales' romantic dreams force her to face her tragic past. | D3894: 1000 | E3894: 0 | F3894: failed | G3894: US | H3894: USD | I3894: 1408863600 | J3894: 1408203557 | K3894: FALSE | L3894: 0 | M3894: FALSE | N3894: theater/plays | O3894: =(E3894/D3894)*100 -> 0 | P3894: =IF(E3894>0,E3894/L3894,"N/A") -> N/A | Q3894: theater | R3894: plays | S3894: =(((J3894/60)/60)/24)+DATE(1970,1,1) -> 41867.652 | T3894: =(((I3894/60)/60/24)+DATE(1970,1,1)) -> 41875.292
A3895: 3893 | B3895: MY PRIVATE REVOLUTION | C3895: An inspiring story of a young girl's journey from childhood to adulthood told through monologue, dialogue, poetry and music and dance. | D3895: 50000 | E3895: 10775 | F3895: failed | G3895: US | H3895: USD | I3895: 1404194400 | J3895: 1400600840 | K3895: FALSE | L3895: 84 | M3895: FALSE | N3895: theater/plays | O3895: =(E3895/D3895)*100 -> 21.55 | P3895: =IF(E3895>0,E3895/L3895,"N/A") -> 128.27381 | Q3895: theater | R3895: plays | S3895: =(((J3895/60)/60)/24)+DATE(1970,1,1) -> 41779.658 | T3895: =(((I3895/60)/60/24)+DATE(1970,1,1)) -> 41821.25
A3896: 3894 | B3896: MADE-UP: A Sitcom Theater Special | C3896: Ryan and Vanessa are hosting Christmas for the first time but instead of a happy celebration, they get a hilarious survival situation. | D3896: 15000 | E3896: 520 | F3896: failed | G3896: US | H3896: USD | I3896: 1481000340 | J3896: 1478386812 | K3896: FALSE | L3896: 11 | M3896: FALSE | N3896: theater/plays | O3896: =(E3896/D3896)*100 -> 3.4666667 | P3896: =IF(E3896>0,E3896/L3896,"N/A") -> 47.272727 | Q3896: theater | R3896: plays | S3896: =(((J3896/60)/60)/24)+DATE(1970,1,1) -> 42679.958 | T3896: =(((I3896/60)/60/24)+DATE(1970,1,1)) -> 42710.208
A3897: 3895 | B3897: Vestige | C3897: A Transgender makeup artist calls into question the loyalty of her best friend in a 1980's circus while dealing with her dying mother. | D3897: 1000 | E3897: 50 | F3897: failed | G3897: US | H3897: USD | I3897: 1425103218 | J3897: 1422424818 | K3897: FALSE | L3897: 1 | M3897: FALSE | N3897: theater/plays | O3897: =(E3897/D3897)*100 -> 5 | P3897: =IF(E3897>0,E3897/L3897,"N/A") -> 50 | Q3897: theater | R3897: plays | S3897: =(((J3897/60)/60)/24)+DATE(1970,1,1) -> 42032.25 | T3897: =(((I3897/60)/60/24)+DATE(1970,1,1)) -> 42063.25
A3898: 3896 | B3898: Yorick and Company | C3898: Yorick and Co. is a comedy about a struggling theatre company whose mysterious benefactor starts haunting the show! | D3898: 1600 | E3898: 170 | F3898: failed | G3898: US | H3898: USD | I3898: 1402979778 | J3898: 1401770178 | K3898: FALSE | L3898: 4 | M3898: FALSE | N3898: theater/plays | O3898: =(E3898/D3898)*100 -> 10.625 | P3898: =IF(E3898>0,E3898/L3898,"N/A") -> 42.5 | Q3898: theater | R3898: plays | S3898: =(((J3898/60)/60)/24)+DATE(1970,1,1) -> 41793.192 | T3898: =(((I3898/60)/60/24)+DATE(1970,1,1)) -> 41807.192
A3899: 3897 | B3899: Terry Pratchett's Wyrd Sisters at Paeroa Little Theatre | C3899: Help us to put on a production of Terry Pratchett's Wyrd Sisters, an ambitions show for our theatre but one I believe we can do. | D3899: 2500 | E3899: 440 | F3899: failed | G3899: NZ | H3899: NZD | I3899: 1420750683 | J3899: 1418158683 | K3899: FALSE | L3899: 10 | M3899: FALSE | N3899: theater/plays | O3899: =(E3899/D3899)*100 -> 17.6 | P3899: =IF(E3899>0,E3899/L3899,"N/A") -> 44 | Q3899: theater | R3899: plays | S3899: =(((J3899/60)/60)/24)+DATE(1970,1,1) -> 41982.874 | T3899: =(((I3899/60)/60/24)+DATE(1970,1,1)) -> 42012.874
...

Sheet Category Pivot Table
A1: country | B1: (All)
A3: Count of Outcome | B3: Column Labels
A4: Row Labels | B4: successful | C4: failed | D4: canceled | E4: live | F4: Grand Total
A5: film & video | B5: 300 | C5: 180 | D5: 40 | F5: 520
A6: food | B6: 34 | C6: 140 | D6: 20 | E6: 6 | F6: 200
A7: games | B7: 80 | C7: 140 | F7: 220
A8: journalism | D8: 24 | F8: 24
A9: music | B9: 540 | C9: 120 | D9: 20 | E9: 20 | F9: 700
A10: photography | B10: 103 | C10: 117 | F10: 220
A11: publishing | B11: 80 | C11: 127 | D11: 30 | F11: 237
A12: technology | B12: 209 | C12: 213 | D12: 178 | F12: 600
A13: theater | B13: 839 | C13: 493 | D13: 37 | E13: 24 | F13: 1393
A14: Grand Total | B14: 2185 | C14: 1530 | D14: 349 | E14: 50 | F14: 4114

Sheet sub-category Pivot Table
A1: country | B1: (All)
A2: Category | B2: (All)
A4: Count of outcome | B4: Column Labels
A5: Row Labels | B5: successful | C5: failed | D5: canceled | E5: live | F5: Grand Total
A6: animation | C6: 100 | F6: 100
A7: art books | D7: 20 | F7: 20
A8: audio | D8: 24 | F8: 24
A9: children's books | C9: 40 | F9: 40
A10: classical music | B10: 40 | F10: 40
A11: documentary | B11: 180 | F11: 180
A12: drama | C12: 80 | F12: 80
A13: electronic music | B13: 40 | F13: 40
A14: faith | C14: 40 | E14: 20 | F14: 60
A15: fiction | C15: 40 | F15: 40
A16: food trucks | C16: 120 | D16: 20 | F16: 140
A17: gadgets | C17: 20 | F17: 20
A18: hardware | B18: 140 | F18: 140
A19: indie rock | B19: 140 | C19: 20 | F19: 160
A20: jazz | C20: 60 | F20: 60
A21: makerspaces | B21: 9 | C21: 11 | F21: 20
A22: metal | B22: 20 | F22: 20
A23: mobile games | C23: 40 | F23: 40
A24: musical | B24: 60 | C24: 60 | D24: 20 | F24: 140
A25: nature | C25: 20 | F25: 20
A26: nonfiction | B26: 60 | F26: 60
A27: people | C27: 20 | F27: 20
A28: photobooks | B28: 103 | C28: 57 | F28: 160
A29: places | C29: 20 | F29: 20
A30: plays | B30: 694 | C30: 353 | E30: 19 | F30: 1066
A31: pop | B31: 40 | F31: 40
A32: radio & podcasts | B32: 20 | F32: 20
A33: restaurants | C33: 20 | F33: 20
A34: rock | B34: 260 | F34: 260
A35: science fiction | D35: 40 | F35: 40
A36: shorts | B36: 60 | F36: 60
A37: small batch | B37: 34 | E37: 6 | F37: 40
A38: space exploration | B38: 40 | C38: 2 | D38: 18 | F38: 60
A39: spaces | B39: 85 | C39: 80 | D39: 17 | E39: 5 | F39: 187
A40: tabletop games | B40: 80 | F40: 80
A41: television | B41: 60 | F41: 60
...

Sheet Pivot Chart
A1: Category | B1: (All)
A2: Years | B2: (All)
A4: Count of outcome | B4: Column Labels
A5: Row Labels | B5: successful | C5: failed | D5: canceled | E5: Grand Total
A6: Jan | B6: 182 | C6: 149 | D6: 34 | E6: 365
A7: Feb | B7: 202 | C7: 106 | D7: 27 | E7: 335
A8: Mar | B8: 180 | C8: 108 | D8: 28 | E8: 316
A9: Apr | B9: 192 | C9: 102 | D9: 27 | E9: 321
A10: May | B10: 234 | C10: 126 | D10: 26 | E10: 386
A11: Jun | B11: 211 | C11: 147 | D11: 27 | E11: 385
A12: Jul | B12: 194 | C12: 150 | D12: 43 | E12: 387
A13: Aug | B13: 166 | C13: 134 | D13: 33 | E13: 333
A14: Sep | B14: 147 | C14: 127 | D14: 24 | E14: 298
A15: Oct | B15: 183 | C15: 149 | D15: 20 | E15: 352
A16: Nov | B16: 183 | C16: 114 | D16: 37 | E16: 334
A17: Dec | B17: 111 | C17: 118 | D17: 23 | E17: 252
A18: Grand Total | B18: 2185 | C18: 1530 | D18: 349 | E18: 4064

Sheet Bonus
A1: Goal | B1: Number Successful | C1: Number Failed | D1: Number Canceled | E1: Total Projects | F1: Percentage Successful | G1: Percentage Failed | H1: Percentage Canceled
A2: < 1000 | B2: =COUNTIFS(Sheet1!$F:$F,"*successful*",Sheet1!$D:$D,"<1000") -> 322 | C2: =COUNTIFS(Sheet1!$F:$F,"*failed*",Sheet1!$D:$D,"<1000") -> 113 | D2: =COUNTIFS(Sheet1!$F:$F,"*canceled*",Sheet1!$D:$D,"<1000") -> 18 | E2: =SUM(B2:D2) -> 453 | F2: =B2/$E2 -> 0.71081678 | G2: =C2/$E2 -> 0.24944812 | H2: =D2/$E2 -> 0.039735099
A3: 1000 to 4999 | B3: =COUNTIFS(Sheet1!$F:$F,"*successful*",Sheet1!$D:$D,"<=4999") -> 1254 | C3: =COUNTIFS(Sheet1!$F:$F,"*failed*",Sheet1!$D:$D,"<=4999") -> 533 | D3: =COUNTIFS(Sheet1!$F:$F,"*canceled*",Sheet1!$D:$D,"<=4999") -> 78 | E3: =SUM(B3:D3) -> 1865 | F3: =B3/$E3 -> 0.67238606 | G3: =C3/$E3 -> 0.28579088 | H3: =D3/$E3 -> 0.041823056
A4: 5000 to 9999 | B4: =COUNTIFS(Sheet1!$F:$F,"*successful*",Sheet1!$D:$D,"<=9999") -> 1635 | C4: =COUNTIFS(Sheet1!$F:$F,"*failed*",Sheet1!$D:$D,"<=9999") -> 816 | D4: =COUNTIFS(Sheet1!$F:$F,"*canceled*",Sheet1!$D:$D,"<=9999") -> 130 | E4: =SUM(B4:D4) -> 2581 | F4: =B4/$E4 -> 0.6334754 | G4: =C4/$E4 -> 0.31615653 | H4: =D4/$E4 -> 0.050368074
A5: 10000 to 14999 | B5: =COUNTIFS(Sheet1!$F:$F,"*successful*",Sheet1!$D:$D,"<=14999") -> 1803 | C5: =COUNTIFS(Sheet1!$F:$F,"*failed*",Sheet1!$D:$D,"<=14999") -> 960 | D5: =COUNTIFS(Sheet1!$F:$F,"*canceled*",Sheet1!$D:$D,"<=14999") -> 170 | E5: =SUM(B5:D5) -> 2933 | F5: =B5/$E5 -> 0.61472895 | G5: =C5/$E5 -> 0.32730992 | H5: =D5/$E5 -> 0.057961132
A6: 15000 to 19999 | B6: =COUNTIFS(Sheet1!$F:$F,"*successful*",Sheet1!$D:$D,"<=19999") -> 1897 | C6: =COUNTIFS(Sheet1!$F:$F,"*failed*",Sheet1!$D:$D,"<=19999") -> 1050 | D6: =COUNTIFS(Sheet1!$F:$F,"*canceled*",Sheet1!$D:$D,"<=19999") -> 187 | E6: =SUM(B6:D6) -> 3134 | F6: =B6/$E6 -> 0.60529675 | G6: =C6/$E6 -> 0.3350351 | H6: =D6/$E6 -> 0.059668156
A7: 20000 to 24999 | B7: =COUNTIFS(Sheet1!$F:$F,"*successful*",Sheet1!$D:$D,"<=24999") -> 1959 | C7: =COUNTIFS(Sheet1!$F:$F,"*failed*",Sheet1!$D:$D,"<=24999") -> 1122 | D7: =COUNTIFS(Sheet1!$F:$F,"*canceled*",Sheet1!$D:$D,"<=24999") -> 201 | E7: =SUM(B7:D7) -> 3282 | F7: =B7/$E7 -> 0.59689214 | G7: =C7/$E7 -> 0.34186472 | H7: =D7/$E7 -> 0.061243144
A8: 25000 to 29999 | B8: =COUNTIFS(Sheet1!$F:$F,"*successful*",Sheet1!$D:$D,"<=29999") -> 2014 | C8: =COUNTIFS(Sheet1!$F:$F,"*failed*",Sheet1!$D:$D,"<=29999") -> 1186 | D8: =COUNTIFS(Sheet1!$F:$F,"*canceled*",Sheet1!$D:$D,"<=29999") -> 219 | E8: =SUM(B8:D8) -> 3419 | F8: =B8/$E8 -> 0.58906113 | G8: =C8/$E8 -> 0.34688505 | H8: =D8/$E8 -> 0.064053817
A9: 30000 to 34999 | B9: =COUNTIFS(Sheet1!$F:$F,"*successful*",Sheet1!$D:$D,"<=34999") -> 2046 | C9: =COUNTIFS(Sheet1!$F:$F,"*failed*",Sheet1!$D:$D,"<=34999") -> 1223 | D9: =COUNTIFS(Sheet1!$F:$F,"*canceled*",Sheet1!$D:$D,"<=34999") -> 232 | E9: =SUM(B9:D9) -> 3501 | F9: =B9/$E9 -> 0.58440446 | G9: =C9/$E9 -> 0.34932876 | H9: =D9/$E9 -> 0.066266781
A10: 35000 to 39999 | B10: =COUNTIFS(Sheet1!$F:$F,"*successful*",Sheet1!$D:$D,"<=39999") -> 2072 | C10: =COUNTIFS(Sheet1!$F:$F,"*failed*",Sheet1!$D:$D,"<=39999") -> 1245 | D10: =COUNTIFS(Sheet1!$F:$F,"*canceled*",Sheet1!$D:$D,"<=39999") -> 239 | E10: =SUM(B10:D10) -> 3556 | F10: =B10/$E10 -> 0.58267717 | G10: =C10/$E10 -> 0.35011249 | H10: =D10/$E10 -> 0.067210349
A11: 40000 to 44999 | B11: =COUNTIFS(Sheet1!$F:$F,"*successful*",Sheet1!$D:$D,"<=44999") -> 2093 | C11: =COUNTIFS(Sheet1!$F:$F,"*failed*",Sheet1!$D:$D,"<=44999") -> 1261 | D11: =COUNTIFS(Sheet1!$F:$F,"*canceled*",Sheet1!$D:$D,"<=44999") -> 245 | E11: =SUM(B11:D11) -> 3599 | F11: =B11/$E11 -> 0.58155043 | G11: =C11/$E11 -> 0.3503751 | H11: =D11/$E11 -> 0.068074465
A12: 45000 to 49999 | B12: =COUNTIFS(Sheet1!$F:$F,"*successful*",Sheet1!$D:$D,"<=49999") -> 2099 | C12: =COUNTIFS(Sheet1!$F:$F,"*failed*",Sheet1!$D:$D,"<=49999") -> 1272 | D12: =COUNTIFS(Sheet1!$F:$F,"*canceled*",Sheet1!$D:$D,"<=49999") -> 249 | E12: =SUM(B12:D12) -> 3620 | F12: =B12/$E12 -> 0.57983425 | G12: =C12/$E12 -> 0.35138122 | H12: =D12/$E12 -> 0.06878453
A13: >= 50000 | B13: =COUNTIFS(Sheet1!$F:$F,"*successful*",Sheet1!$D:$D,">=50000") -> 86 | C13: =COUNTIFS(Sheet1!$F:$F,"*failed*",Sheet1!$D:$D,">=50000") -> 258 | D13: =COUNTIFS(Sheet1!$F:$F,"*canceled*",Sheet1!$D:$D,">=50000") -> 100 | E13: =SUM(B13:D13) -> 444 | F13: =B13/$E13 -> 0.19369369 | G13: =C13/$E13 -> 0.58108108 | H13: =D13/$E13 -> 0.22522523

Sheet Bonus Stat An
A1: successful outcome | B1: backers_count | C1: failed outcome | D1: backers_count | F1: Successful backers
A2: successful | B2: 182 | C2: failed | D2: 0 | F2: Mean | G2: =AVERAGE(B2:B2186) -> 194.42517
A3: successful | B3: 79 | C3: failed | D3: 1 | F3: Median | G3: =MEDIAN(B2:B2186) -> 62
A4: successful | B4: 35 | C4: failed | D4: 10 | F4: Minimum | G4: =MIN(B2:B2186) -> 1
A5: successful | B5: 150 | C5: failed | D5: 0 | F5: Maximum | G5: =MAX(B2:B2186) -> 26457
A6: successful | B6: 284 | C6: failed | D6: 7 | F6: Variance | G6: =_xlfn.VAR.P(B2:B2186) -> 712840.99
A7: successful | B7: 47 | C7: failed | D7: 0 | F7: Standard Dev | G7: =_xlfn.STDEV.P(B2:B2186) -> 844.29911
A8: successful | B8: 58 | C8: failed | D8: 1
A9: successful | B9: 57 | C9: failed | D9: 2
A10: successful | B10: 12 | C10: failed | D10: 3 | F10: Failed backers
A11: successful | B11: 20 | C11: failed | D11: 10 | F11: Mean | G11: =AVERAGE(D11:D1531) -> 17.798817
A12: successful | B12: 19 | C12: failed | D12: 10 | F12: Median | G12: =MEDIAN(D11:D1531) -> 4
A13: successful | B13: 75 | C13: failed | D13: 1 | F13: Minimum | G13: =MIN(D11:D1531) -> 0
A14: successful | B14: 827 | C14: failed | D14: 0 | F14: Maximum | G14: =MAX(D11:D1531) -> 1293
A15: successful | B15: 51 | C15: failed | D15: 0 | F15: Variance | G15: =_xlfn.VAR.P(D11:D1531) -> 3794.1357
A16: successful | B16: 41 | C16: failed | D16: 0 | F16: Standard Dev | G16: =_xlfn.STDEV.P(D11:D1531) -> 61.596556
A17: successful | B17: 98 | C17: failed | D17: 26
A18: successful | B18: 70 | C18: failed | D18: 0
A19: successful | B19: 36 | C19: failed | D19: 7
A20: successful | B20: 342 | C20: failed | D20: 0
A21: successful | B21: 22 | C21: failed | D21: 2
A22: successful | B22: 25 | C22: failed | D22: 13
A23: successful | B23: 101 | C23: failed | D23: 4
A24: successful | B24: 8 | C24: failed | D24: 0
A25: successful | B25: 23 | C25: failed | D25: 12
A26: successful | B26: 574 | C26: failed | D26: 2
A27: successful | B27: 14 | C27: failed | D27: 10
A28: successful | B28: 19 | C28: failed | D28: 0
... A1531: successful | B1531: 128 | C1531: failed | D1531: 3
A1532: successful | B1532: 15
A1533: successful | B1533: 25
A1534: successful | B1534: 55
A1535: successful | B1535: 107
A1536: successful | B1536: 557
A1537: successful | B1537: 40
A1538: successful | B1538: 36
A1539: successful | B1539: 159
A1540: successful | B1540: 41
A1541: successful | B1541: 226
A1542: successful | B1542: 30
...
